<?xml version="1.0" encoding="utf-8"?>
<!-- =================================================================================== -->
<!-- |    This document was autogenerated by xacro from ommp_sim.urdf.xacro            | -->
<!-- |    EDITING THIS FILE BY HAND IS NOT RECOMMENDED                                 | -->
<!-- =================================================================================== -->
<robot name="ommp_sim">
  <!--INCLUDE MACROS-->
  <!-- Link sizes -->
  <!-- Gripper Origings -->
  <!-- Kinect Sensor -->
  <!-- wheels-->
  <!--Robot bases-->
  <!-- imu-->
  <!-- kinect base-->
  <!-- Include Sensors macros -->
  <!---->
  <!-- hokuyo -->
  <gazebo reference="laser_link">
    <sensor name="ydlidar" type="gpu_ray">
      <pose>0 0 0 0 0 0</pose>
      <visualize>false</visualize>
      <update_rate>40</update_rate>
      <ray>
        <scan>
          <horizontal>
            <samples>720</samples>
            <resolution>1</resolution>
            <min_angle>-3.14</min_angle>
            <max_angle>3.14</max_angle>
          </horizontal>
        </scan>
        <range>
          <min>0.3</min>
          <max>50.0</max>
          <resolution>0.01</resolution>
        </range>
        <noise>
          <type>gaussian</type>
          <!-- Noise parameters based on published spec for Hokuyo laser
               achieving "+-30mm" accuracy at range < 10m.  A mean of 0.0m and
               stddev of 0.01m will put 99.7% of samples within 0.03m of the true
               reading. -->
          <mean>0.0</mean>
          <stddev>0.0</stddev>
        </noise>
      </ray>
      <plugin filename="libgazebo_ros_gpu_laser.so" name="gazebo_ros_head_ydlidar_controller">
        <topicName>/scan</topicName>
        <frameName>laser_link</frameName>
      </plugin>
    </sensor>
  </gazebo>
  <gazebo>
    <plugin filename="libhector_gazebo_ros_imu.so" name="imu_controller">
      <robotNamespace>/</robotNamespace>
      <updateRate>50.0</updateRate>
      <bodyName>imu_link</bodyName>
      <topicName>imu/data</topicName>
      <accelDrift>0.005 0.005 0.005</accelDrift>
      <accelGaussianNoise>0.005 0.005 0.005</accelGaussianNoise>
      <rateDrift>0.005 0.005 0.005 </rateDrift>
      <rateGaussianNoise>0.005 0.005 0.005 </rateGaussianNoise>
      <headingDrift>0.005</headingDrift>
      <headingGaussianNoise>0.005</headingGaussianNoise>
    </plugin>
  </gazebo>
  <gazebo reference="imu_link">
    <turnGravityOff>false</turnGravityOff>
  </gazebo>
  <!-- Microsoft Kinect / ASUS Xtion PRO Live for simulation -->
  <!--
          <CxPrime>0</CxPrime>
          <Cx>0</Cx>
          <Cy>0</Cy>
          <focalLength>0</focalLength>
          <hackBaseline>0</hackBaseline>
      -->
  <gazebo reference="camera_depth_frame">
    <sensor name="my_camera" type="depth">
      <always_on>true</always_on>
      <update_rate>20.0</update_rate>
      <camera>
        <horizontal_fov>1.047197551</horizontal_fov>
        <image>
          <format>R8G8B8</format>
          <width>640</width>
          <height>480</height>
        </image>
        <clip>
          <near>0.05</near>
          <far>8.0</far>
        </clip>
      </camera>
      <plugin filename="libgazebo_ros_openni_kinect.so" name="camera_depth_frame_kinect_controller">
        <baseline>0.1</baseline>
        <alwaysOn>true</alwaysOn>
        <updateRate>10</updateRate>
        <cameraName>my_camera</cameraName>
        <imageTopicName>rgb/image_raw</imageTopicName>
        <cameraInfoTopicName>rgb/camera_info</cameraInfoTopicName>
        <depthImageTopicName>depth_registered/image_raw</depthImageTopicName>
        <depthImageCameraInfoTopicName>depth/camera_info</depthImageCameraInfoTopicName>
        <pointCloudTopicName>depth_registered/points</pointCloudTopicName>
        <frameName>camera_depth_optical_frame</frameName>
        <pointCloudCutoff>0.3</pointCloudCutoff>
        <distortion_k1>0.0</distortion_k1>
        <distortion_k2>0.0</distortion_k2>
        <distortion_k3>0.0</distortion_k3>
        <distortion_t1>0.0</distortion_t1>
        <distortion_t2>0.0</distortion_t2>
      </plugin>
    </sensor>
  </gazebo>
  <!-- remove if Kinect isn't moving -->
  <transmission name="kinect_mount_tranms">
    <type>transmission_interface/SimpleTransmission</type>
    <joint name="camera_rgb_joint">
      <hardwareInterface>hardware_interface/PositionJointInterface</hardwareInterface>
    </joint>
    <actuator name="kinect_mount_act">
      <mechanicalReduction>1</mechanicalReduction>
      <hardwareInterface>hardware_interface/PositionJointInterface</hardwareInterface>
    </actuator>
  </transmission>
  <!-- Parameterised in part by the values in kinect_properties.urdf.xacro -->
  <!---->
  <gazebo reference="chassis">
    <material>Gazebo/Red</material>
  </gazebo>
  <gazebo reference="upper_base">
    <material>Gazebo/Black</material>
  </gazebo>
  <gazebo reference="kinect_base1">
    <material>Gazebo/Blue</material>
  </gazebo>
  <gazebo reference="kinect_base2">
    <material>Gazebo/Red</material>
  </gazebo>
  <!-- Wheels -->
  <transmission name="shoulder_pan_trans">
    <type>transmission_interface/SimpleTransmission</type>
    <joint name="shoulder_pan_joint">
      <hardwareInterface>hardware_interface/EffortJointInterface</hardwareInterface>
    </joint>
    <actuator name="shoulder_pan_motor">
      <mechanicalReduction>1</mechanicalReduction>
    </actuator>
  </transmission>
  <transmission name="shoulder_lift_trans">
    <type>transmission_interface/SimpleTransmission</type>
    <joint name="shoulder_lift_joint">
      <hardwareInterface>hardware_interface/EffortJointInterface</hardwareInterface>
    </joint>
    <actuator name="shoulder_lift_motor">
      <mechanicalReduction>1</mechanicalReduction>
    </actuator>
  </transmission>
  <transmission name="elbow_trans">
    <type>transmission_interface/SimpleTransmission</type>
    <joint name="elbow_joint">
      <hardwareInterface>hardware_interface/EffortJointInterface</hardwareInterface>
    </joint>
    <actuator name="elbow_motor">
      <mechanicalReduction>1</mechanicalReduction>
    </actuator>
  </transmission>
  <transmission name="wrist_1_trans">
    <type>transmission_interface/SimpleTransmission</type>
    <joint name="wrist_1_joint">
      <hardwareInterface>hardware_interface/EffortJointInterface</hardwareInterface>
    </joint>
    <actuator name="wrist_1_motor">
      <mechanicalReduction>1</mechanicalReduction>
    </actuator>
  </transmission>
  <transmission name="wrist_2_trans">
    <type>transmission_interface/SimpleTransmission</type>
    <joint name="wrist_2_joint">
      <hardwareInterface>hardware_interface/EffortJointInterface</hardwareInterface>
    </joint>
    <actuator name="wrist_2_motor">
      <mechanicalReduction>1</mechanicalReduction>
    </actuator>
  </transmission>
  <transmission name="wrist_3_trans">
    <type>transmission_interface/SimpleTransmission</type>
    <joint name="wrist_3_joint">
      <hardwareInterface>hardware_interface/EffortJointInterface</hardwareInterface>
    </joint>
    <actuator name="wrist_3_motor">
      <mechanicalReduction>1</mechanicalReduction>
    </actuator>
  </transmission>
  <gazebo reference="arm_base">
    <material>Gazebo/Blue</material>
    <mu1>0.2</mu1>
    <mu2>0.2</mu2>
    <selfCollide>true</selfCollide>
  </gazebo>
  <gazebo reference="shoulder_link">
    <material>Gazebo/Green</material>
    <mu1>0.2</mu1>
    <mu2>0.2</mu2>
    <selfCollide>true</selfCollide>
  </gazebo>
  <gazebo reference="upper_arm_link">
    <material>Gazebo/Black</material>
    <mu1>0.2</mu1>
    <mu2>0.2</mu2>
    <selfCollide>true</selfCollide>
  </gazebo>
  <gazebo reference="forearm_link">
    <material>Gazebo/Yellow</material>
    <mu1>0.2</mu1>
    <mu2>0.2</mu2>
    <selfCollide>true</selfCollide>
  </gazebo>
  <gazebo reference="wrist_1_link">
    <material>Gazebo/Blue</material>
    <mu1>0.2</mu1>
    <mu2>0.2</mu2>
    <selfCollide>true</selfCollide>
  </gazebo>
  <gazebo reference="wrist_2_link">
    <material>Gazebo/Black</material>
    <mu1>0.2</mu1>
    <mu2>0.2</mu2>
    <selfCollide>true</selfCollide>
  </gazebo>
  <gazebo reference="wrist_3_link">
    <material>Gazebo/Green</material>
    <mu1>0.2</mu1>
    <mu2>0.2</mu2>
    <selfCollide>true</selfCollide>
  </gazebo>
  <!--Macro of the arm -->
  <transmission name="finger1_trans">
    <type>transmission_interface/SimpleTransmission</type>
    <joint name="finger1_joint">
      <hardwareInterface>hardware_interface/EffortJointInterface</hardwareInterface>
    </joint>
    <actuator name="finger1_motor">
      <mechanicalReduction>1</mechanicalReduction>
    </actuator>
  </transmission>
  <transmission name="finger2_trans">
    <type>transmission_interface/SimpleTransmission</type>
    <joint name="finger2_joint">
      <hardwareInterface>hardware_interface/EffortJointInterface</hardwareInterface>
    </joint>
    <actuator name="finger2_motor">
      <mechanicalReduction>1</mechanicalReduction>
    </actuator>
  </transmission>
  <gazebo reference="ee_base">
    <material>Gazebo/Red</material>
    <mu1>0.2</mu1>
    <mu2>0.2</mu2>
    <selfCollide>true</selfCollide>
  </gazebo>
  <gazebo reference="finger1">
    <material>Gazebo/Black</material>
    <mu1>300</mu1>
    <mu2>300</mu2>
    <kd>1.0</kd>
    <kp>1000000.0</kp>
    <selfCollide>true</selfCollide>
  </gazebo>
  <gazebo reference="finger2">
    <material>Gazebo/Black</material>
    <mu1>300</mu1>
    <mu2>300</mu2>
    <kd>1.0</kd>
    <kp>1000000.0</kp>
    <selfCollide>true</selfCollide>
  </gazebo>
  <!-- ros_control plugin -->
  <gazebo>
    <plugin filename="libgazebo_ros_control.so" name="gazebo_ros_control">
      <!--legacyModeNS>true</legacyModeNS-->
      <robotSimType>gazebo_ros_control/DefaultRobotHWSim</robotSimType>
    </plugin>
  </gazebo>
  <!--INSTANTIATE MACROS-->
  <link name="robot_footprint"/>
  <joint name="robot_footprint_joint" type="fixed">
    <origin rpy="0 0 0" xyz="0 0 0"/>
    <parent link="robot_footprint"/>
    <child link="chassis"/>
  </joint>
  <link name="chassis">
    <inertial>
      <origin rpy="0 0 0" xyz="0 0 0"/>
      <mass value="100"/>
      <inertia ixx="0.3136" ixy="0" ixz="0" iyy="0.3922" iyz="0" izz="0.4485"/>
    </inertial>
    <collision name="collision">
      <origin rpy=" 0 0 0" xyz="0 0 0"/>
      <geometry>
        <box size="0.25 0.2 0.06"/>
      </geometry>
    </collision>
    <visual name="chassis_visual">
      <origin rpy=" 0 0 0" xyz="0 0 0"/>
      <geometry>
        <box size="0.25 0.2 0.06"/>
      </geometry>
      <material name="green">
        <color rgba="0 1 0 1"/>
      </material>
    </visual>
  </link>
  <link name="upper_base">
    <inertial>
      <mass value="0.01"/>
      <origin rpy="0 0 0" xyz="0 0 0"/>
      <inertia ixx="0.0000001" ixy="0" ixz="0" iyy="0.0000001" iyz="0" izz="0.0000001"/>
    </inertial>
    <visual>
      <geometry>
        <box size="0.3 0.15 0.02"/>
      </geometry>
      <origin rpy="0 0 0" xyz="0 0 0"/>
      <material name="red">
        <color rgba="1 0 0 1"/>
      </material>
    </visual>
    <collision>
      <geometry>
        <box size="0.3 0.15 0.02"/>
      </geometry>
      <origin rpy="0 0 0" xyz="0 0 0"/>
    </collision>
  </link>
  <joint name="upper_base_joint" type="fixed">
    <origin rpy="0 0 0" xyz="0.05 0.0 0.0875"/>
    <parent link="chassis"/>
    <child link="upper_base"/>
  </joint>
  <link name="kinect_base1">
    <inertial>
      <mass value="0.01"/>
      <origin rpy="0 0 0" xyz="0 0 0"/>
      <inertia ixx="0.0000001" ixy="0" ixz="0" iyy="0.0000001" iyz="0" izz="0.0000001"/>
    </inertial>
    <visual>
      <geometry>
        <box size="0.01 0.03 0.38"/>
      </geometry>
      <origin rpy="0 0 0" xyz="0 0 0"/>
      <material name="green">
        <color rgba="0 1 0 1"/>
      </material>
    </visual>
    <collision>
      <geometry>
        <box size="0.01 0.03 0.38"/>
      </geometry>
      <origin rpy="0 0 0" xyz="0 0 0"/>
    </collision>
  </link>
  <joint name="kinect_base_joint1" type="fixed">
    <origin rpy="0 0 0" xyz="-0.14 0.0 0.2"/>
    <parent link="upper_base"/>
    <child link="kinect_base1"/>
  </joint>
  <link name="kinect_base2">
    <inertial>
      <mass value="0.01"/>
      <origin rpy="0 0 0" xyz="0 0 0"/>
      <inertia ixx="0.0000001" ixy="0" ixz="0" iyy="0.0000001" iyz="0" izz="0.0000001"/>
    </inertial>
    <visual>
      <geometry>
        <box size="0.07 0.07 0.02"/>
      </geometry>
      <origin rpy="0 0 0" xyz="0 0 0"/>
      <material name="red">
        <color rgba="1 0 0 1"/>
      </material>
    </visual>
    <collision>
      <geometry>
        <box size="0.07 0.07 0.02"/>
      </geometry>
      <origin rpy="0 0 0" xyz="0 0 0"/>
    </collision>
  </link>
  <joint name="kinect_base_joint2" type="fixed">
    <origin rpy="0 0 0" xyz="0.035 0.0 0.19"/>
    <parent link="kinect_base1"/>
    <child link="kinect_base2"/>
  </joint>
  <joint name="front_left_wheel_joint" type="continuous">
    <parent link="chassis"/>
    <child link="front_left_wheel_link"/>
    <origin rpy="0 0 0" xyz="0.0975 0.14 -0.015"/>
    <axis rpy="0 0 0" xyz="0 1 0"/>
  </joint>
  <link name="front_left_wheel_link">
    <visual>
      <origin rpy="1.5707963265 0 0" xyz="0 0 0"/>
      <geometry>
        <cylinder length="0.065" radius="0.055"/>
      </geometry>
      <material name="blue">
        <color rgba="1 0 0 1"/>
      </material>
    </visual>
    <collision>
      <geometry>
        <cylinder length="0.065" radius="0.055"/>
      </geometry>
      <origin rpy="1.5707963265 0 0" xyz="0 0 0"/>
    </collision>
    <inertial>
      <origin rpy="0 0 0" xyz="0 0 0"/>
      <mass value="0.477"/>
      <inertia ixx="0.0013" ixy="0" ixz="0" iyy="0.0024" iyz="0" izz="0.0013"/>
    </inertial>
  </link>
  <!-- Transmission is important to link the joints and the controller-->
  <transmission name="front_left_wheel_joint_trans">
    <type>transmission_interface/SimpleTransmission</type>
    <joint name="front_left_wheel_joint">
      <hardwareInterface>hardware_interface/VelocityJointInterface</hardwareInterface>
    </joint>
    <actuator name="front_left_wheel_joint_motor">
      <mechanicalReduction>1</mechanicalReduction>
    </actuator>
  </transmission>
  <gazebo reference="front_left_wheel_link">
    <mu1 value="0.5"/>
    <mu2 value="0.5"/>
    <kp value="10000000.0"/>
    <kd value="1.0"/>
    <fdir1 value="1 0 0"/>
    <!--turnGravityOff>false</turnGravityOff-->
    <selfCollide>false</selfCollide>
    <material>Gazebo/Blue</material>
  </gazebo>
  <joint name="front_right_wheel_joint" type="continuous">
    <parent link="chassis"/>
    <child link="front_right_wheel_link"/>
    <origin rpy="0 0 0" xyz="0.0975 -0.14 -0.015"/>
    <axis rpy="0 0 0" xyz="0 1 0"/>
  </joint>
  <link name="front_right_wheel_link">
    <visual>
      <origin rpy="1.5707963265 0 0" xyz="0 0 0"/>
      <geometry>
        <cylinder length="0.065" radius="0.055"/>
      </geometry>
      <material name="blue">
        <color rgba="1 0 0 1"/>
      </material>
    </visual>
    <collision>
      <geometry>
        <cylinder length="0.065" radius="0.055"/>
      </geometry>
      <origin rpy="1.5707963265 0 0" xyz="0 0 0"/>
    </collision>
    <inertial>
      <origin rpy="0 0 0" xyz="0 0 0"/>
      <mass value="0.477"/>
      <inertia ixx="0.0013" ixy="0" ixz="0" iyy="0.0024" iyz="0" izz="0.0013"/>
    </inertial>
  </link>
  <!-- Transmission is important to link the joints and the controller-->
  <transmission name="front_right_wheel_joint_trans">
    <type>transmission_interface/SimpleTransmission</type>
    <joint name="front_right_wheel_joint">
      <hardwareInterface>hardware_interface/VelocityJointInterface</hardwareInterface>
    </joint>
    <actuator name="front_right_wheel_joint_motor">
      <mechanicalReduction>1</mechanicalReduction>
    </actuator>
  </transmission>
  <gazebo reference="front_right_wheel_link">
    <mu1 value="0.5"/>
    <mu2 value="0.5"/>
    <kp value="10000000.0"/>
    <kd value="1.0"/>
    <fdir1 value="1 0 0"/>
    <!--turnGravityOff>false</turnGravityOff-->
    <selfCollide>false</selfCollide>
    <material>Gazebo/Blue</material>
  </gazebo>
  <joint name="back_left_wheel_joint" type="continuous">
    <parent link="chassis"/>
    <child link="back_left_wheel_link"/>
    <origin rpy="0 0 0" xyz="-0.0975 0.14 -0.015"/>
    <axis rpy="0 0 0" xyz="0 1 0"/>
  </joint>
  <link name="back_left_wheel_link">
    <visual>
      <origin rpy="1.5707963265 0 0" xyz="0 0 0"/>
      <geometry>
        <cylinder length="0.065" radius="0.055"/>
      </geometry>
      <material name="blue">
        <color rgba="1 0 0 1"/>
      </material>
    </visual>
    <collision>
      <geometry>
        <cylinder length="0.065" radius="0.055"/>
      </geometry>
      <origin rpy="1.5707963265 0 0" xyz="0 0 0"/>
    </collision>
    <inertial>
      <origin rpy="0 0 0" xyz="0 0 0"/>
      <mass value="0.477"/>
      <inertia ixx="0.0013" ixy="0" ixz="0" iyy="0.0024" iyz="0" izz="0.0013"/>
    </inertial>
  </link>
  <!-- Transmission is important to link the joints and the controller-->
  <transmission name="back_left_wheel_joint_trans">
    <type>transmission_interface/SimpleTransmission</type>
    <joint name="back_left_wheel_joint">
      <hardwareInterface>hardware_interface/VelocityJointInterface</hardwareInterface>
    </joint>
    <actuator name="back_left_wheel_joint_motor">
      <mechanicalReduction>1</mechanicalReduction>
    </actuator>
  </transmission>
  <gazebo reference="back_left_wheel_link">
    <mu1 value="0.5"/>
    <mu2 value="0.5"/>
    <kp value="10000000.0"/>
    <kd value="1.0"/>
    <fdir1 value="1 0 0"/>
    <!--turnGravityOff>false</turnGravityOff-->
    <selfCollide>false</selfCollide>
    <material>Gazebo/Blue</material>
  </gazebo>
  <joint name="back_right_wheel_joint" type="continuous">
    <parent link="chassis"/>
    <child link="back_right_wheel_link"/>
    <origin rpy="0 0 0" xyz="-0.0975 -0.14 -0.015"/>
    <axis rpy="0 0 0" xyz="0 1 0"/>
  </joint>
  <link name="back_right_wheel_link">
    <visual>
      <origin rpy="1.5707963265 0 0" xyz="0 0 0"/>
      <geometry>
        <cylinder length="0.065" radius="0.055"/>
      </geometry>
      <material name="blue">
        <color rgba="1 0 0 1"/>
      </material>
    </visual>
    <collision>
      <geometry>
        <cylinder length="0.065" radius="0.055"/>
      </geometry>
      <origin rpy="1.5707963265 0 0" xyz="0 0 0"/>
    </collision>
    <inertial>
      <origin rpy="0 0 0" xyz="0 0 0"/>
      <mass value="0.477"/>
      <inertia ixx="0.0013" ixy="0" ixz="0" iyy="0.0024" iyz="0" izz="0.0013"/>
    </inertial>
  </link>
  <!-- Transmission is important to link the joints and the controller-->
  <transmission name="back_right_wheel_joint_trans">
    <type>transmission_interface/SimpleTransmission</type>
    <joint name="back_right_wheel_joint">
      <hardwareInterface>hardware_interface/VelocityJointInterface</hardwareInterface>
    </joint>
    <actuator name="back_right_wheel_joint_motor">
      <mechanicalReduction>1</mechanicalReduction>
    </actuator>
  </transmission>
  <gazebo reference="back_right_wheel_link">
    <mu1 value="0.5"/>
    <mu2 value="0.5"/>
    <kp value="10000000.0"/>
    <kd value="1.0"/>
    <fdir1 value="1 0 0"/>
    <!--turnGravityOff>false</turnGravityOff-->
    <selfCollide>false</selfCollide>
    <material>Gazebo/Blue</material>
  </gazebo>
  <!-- Instanciate the sensor macros -->
  <!--(The gazebo plugin macros are instanciated on their corresponding xacro files) -->
  <joint name="camera_rgb_joint" type="revolute">
    <origin rpy="0 0 0" xyz="0.03 0.0 0.055"/>
    <parent link="kinect_base2"/>
    <child link="camera_rgb_frame"/>
    <axis rpy="0 0 0" xyz="0 1 0"/>
    <dynamics damping="0.0" friction="0.0"/>
    <limit effort="30" lower="-1.57" upper="1.57" velocity="1.0"/>
    <safety_controller k_position="15" k_velocity="10" soft_lower_limit="-1.57" soft_upper_limit="1.57"/>
  </joint>
  <link name="camera_rgb_frame">
    <inertial>
      <mass value="0.001"/>
      <origin xyz="0 0 0"/>
      <inertia ixx="0.0001" ixy="0.0" ixz="0.0" iyy="0.0001" iyz="0.0" izz="0.0001"/>
    </inertial>
  </link>
  <joint name="camera_rgb_optical_joint" type="fixed">
    <origin rpy="-1.5707963265 0 -1.5707963265" xyz="0 0 0"/>
    <parent link="camera_rgb_frame"/>
    <child link="camera_rgb_optical_frame"/>
  </joint>
  <link name="camera_rgb_optical_frame">
    <inertial>
      <mass value="0.001"/>
      <origin xyz="0 0 0"/>
      <inertia ixx="0.0001" ixy="0.0" ixz="0.0" iyy="0.0001" iyz="0.0" izz="0.0001"/>
    </inertial>
  </link>
  <joint name="camera_joint" type="fixed">
    <origin rpy="0 0 0" xyz="-0.031 0 -0.016"/>
    <parent link="camera_rgb_frame"/>
    <child link="camera_link"/>
  </joint>
  <link name="camera_link">
    <visual>
      <origin rpy="0 0 1.5707963265" xyz="0 0 0"/>
      <geometry>
        <mesh filename="package://ommp_description/meshes/sensors/kinect/kinect.dae"/>
      </geometry>
    </visual>
    <collision>
      <origin rpy="0 0 0" xyz="0.0 0.0 0.0"/>
      <geometry>
        <box size="0.07271 0.27794 0.073"/>
      </geometry>
    </collision>
    <inertial>
      <mass value="0.001"/>
      <origin xyz="0 0 0"/>
      <inertia ixx="0.0001" ixy="0.0" ixz="0.0" iyy="0.0001" iyz="0.0" izz="0.0001"/>
    </inertial>
  </link>
  <!-- The fixed joints & links below are usually published by static_transformers launched by the OpenNi launch 
       files. However, for Gazebo simulation we need them, so we add them here.
       (Hence, don't publish them additionally!) -->
  <joint name="camera_depth_joint" type="fixed">
    <origin rpy="0 0 0" xyz="0 0 0"/>
    <parent link="camera_rgb_frame"/>
    <child link="camera_depth_frame"/>
  </joint>
  <link name="camera_depth_frame">
    <inertial>
      <mass value="0.001"/>
      <origin xyz="0 0 0"/>
      <inertia ixx="0.0001" ixy="0.0" ixz="0.0" iyy="0.0001" iyz="0.0" izz="0.0001"/>
    </inertial>
  </link>
  <joint name="camera_depth_optical_joint" type="fixed">
    <origin rpy="-1.5707963265 0 -1.5707963265" xyz="0 0 0"/>
    <parent link="camera_depth_frame"/>
    <child link="camera_depth_optical_frame"/>
  </joint>
  <link name="camera_depth_optical_frame">
    <inertial>
      <mass value="0.001"/>
      <origin xyz="0 0 0"/>
      <inertia ixx="0.0001" ixy="0.0" ixz="0.0" iyy="0.0001" iyz="0.0" izz="0.0001"/>
    </inertial>
  </link>
  <link name="laser_link">
    <inertial>
      <mass value="0.1"/>
      <origin rpy="0 0 0" xyz="0 0 0.0"/>
      <inertia ixx="1e-6" ixy="0" ixz="0" iyy="1e-6" iyz="0" izz="1e-6"/>
    </inertial>
    <visual>
      <geometry>
        <mesh filename="package://ommp_description/meshes/sensors/ydlidar/ydlidar.dae"/>
      </geometry>
      <origin rpy="0 0 0" xyz="0 0 0"/>
    </visual>
    <collision>
      <origin rpy="0 0 0" xyz="0.0 0.0 0.0"/>
      <geometry>
        <box size="0.0 0.0 0.0"/>
      </geometry>
    </collision>
  </link>
  <joint name="ydlidar_joint" type="fixed">
    <origin rpy="0 0 0" xyz="0.0 0.0 0.0315"/>
    <child link="laser_link"/>
    <parent link="chassis"/>
  </joint>
  <link name="imu_link">
    <inertial>
      <mass value="0.001"/>
      <origin rpy="0 0 0" xyz="0 0 0"/>
      <inertia ixx="1e-6" ixy="0" ixz="0" iyy="1e-6" iyz="0" izz="1e-6"/>
    </inertial>
  </link>
  <joint name="imu_joint" type="fixed">
    <child link="imu_link"/>
    <parent link="chassis"/>
  </joint>
  <!-- Instanciate the Generic Arm macros -->
  <link name="arm_footprint"/>
  <joint name="arm_joint" type="fixed">
    <parent link="upper_base"/>
    <child link="arm_footprint"/>
    <origin rpy="0 0 0" xyz="0.11 0.0 0.02"/>
  </joint>
  <link name="arm_base">
    <visual>
      <origin rpy="0 0 0" xyz="0.0 0.0 0.02"/>
      <geometry>
        <cylinder length="0.04" radius="0.04"/>
      </geometry>
      <material name="Blue">
        <color rgba="0.0 0.0 1.0 1.0"/>
      </material>
    </visual>
    <collision>
      <origin rpy="0 0 0" xyz="0.0 0.0 0.02"/>
      <geometry>
        <cylinder length="0.02" radius="0.02"/>
      </geometry>
    </collision>
    <inertial>
      <mass value="4.0"/>
      <origin rpy="0 0 0" xyz="0.0 0.0 0.02"/>
      <inertia ixx="0.00213333248" ixy="0.0" ixz="0.0" iyy="0.00213333248" iyz="0.0" izz="0.0032"/>
    </inertial>
  </link>
  <joint name="arm_footprint_joint" type="fixed">
    <parent link="arm_footprint"/>
    <child link="arm_base"/>
    <origin rpy="0 0 0" xyz="0.0 0.0 0.0"/>
  </joint>
  <!-- SHOULDER -->
  <link name="shoulder_link">
    <visual>
      <origin rpy="0 0 0" xyz="0.045 0.0 0.02"/>
      <geometry>
        <cylinder length="0.04" radius="0.01"/>
      </geometry>
      <material name="Green">
        <color rgba="0.0 1.0 0.0 1.0"/>
      </material>
    </visual>
    <collision>
      <origin rpy="0 0 0" xyz="0.045 0.0 0.02"/>
      <geometry>
        <cylinder length="0.02" radius="0.005"/>
      </geometry>
    </collision>
    <inertial>
      <mass value="7.778"/>
      <origin rpy="0 0 0" xyz="0.045 0.0 0.02"/>
      <inertia ixx="0.00123151617406" ixy="0.0" ixz="0.0" iyy="0.00123151617406" iyz="0.0" izz="0.0003889"/>
    </inertial>
  </link>
  <joint name="shoulder_pan_joint" type="revolute">
    <parent link="arm_base"/>
    <child link="shoulder_link"/>
    <origin rpy="0 0 0" xyz="0.0 0.0 0.02"/>
    <axis xyz="0 0 1"/>
    <limit effort="330.0" lower="-3.141592653" upper="3.141592653" velocity="2.16"/>
    <dynamics damping="0.0" friction="0.0"/>
  </joint>
  <!--UPPER ARM -->
  <link name="upper_arm_link">
    <visual>
      <origin rpy="0 0 0" xyz="0.0 0.0 0.05525"/>
      <geometry>
        <cylinder length="0.115" radius="0.014"/>
      </geometry>
      <material name="Red">
        <color rgba="1.0 0.0 0.0 1.0"/>
      </material>
    </visual>
    <collision>
      <origin rpy="0 0 0" xyz="0.0 0.0 0.05525"/>
      <geometry>
        <cylinder length="0.0575" radius="0.007"/>
      </geometry>
    </collision>
    <inertial>
      <mass value="12.93"/>
      <origin rpy="0 0 0" xyz="0.0 0.0 0.05525"/>
      <inertia ixx="0.0148835015466" ixy="0.0" ixz="0.0" iyy="0.0148835015466" iyz="0.0" izz="0.00126714"/>
    </inertial>
  </link>
  <joint name="shoulder_lift_joint" type="revolute">
    <parent link="shoulder_link"/>
    <child link="upper_arm_link"/>
    <origin rpy="0 0 0" xyz="0.045 0.0 0.05"/>
    <axis xyz="0 1 0"/>
    <limit effort="330.0" lower="-3.141592653" upper="4.19716778441" velocity="2.16"/>
    <dynamics damping="0.0" friction="0.0"/>
  </joint>
  <!--FOREARM -->
  <link name="forearm_link">
    <visual>
      <origin rpy="0 0 0" xyz="0.0 0.0 0.071"/>
      <geometry>
        <cylinder length="0.142" radius="0.01"/>
      </geometry>
      <material name="Green">
        <color rgba="0.0 1.0 0.0 1.0"/>
      </material>
    </visual>
    <collision>
      <origin rpy="0 0 0" xyz="0.0 0.0 0.071"/>
      <geometry>
        <cylinder length="0.071" radius="0.005"/>
      </geometry>
    </collision>
    <inertial>
      <mass value="3.87"/>
      <origin rpy="0 0 0" xyz="0.0 0.0 0.071"/>
      <inertia ixx="0.00659963736014" ixy="0.0" ixz="0.0" iyy="0.00659963736014" iyz="0.0" izz="0.0001935"/>
    </inertial>
  </link>
  <joint name="elbow_joint" type="revolute">
    <parent link="upper_arm_link"/>
    <child link="forearm_link"/>
    <origin rpy="0 0 0" xyz="-0.02 0.0 0.115"/>
    <axis xyz="0 1 0"/>
    <limit effort="330.0" lower="0.0" upper="3.78122091715" velocity="2.16"/>
    <dynamics damping="0.0" friction="0.0"/>
  </joint>
  <!-- Wrist 1 link -->
  <link name="wrist_1_link">
    <visual>
      <origin rpy="0 0 0" xyz="0.0 0.0 0.01"/>
      <geometry>
        <cylinder length="0.02" radius="0.01"/>
      </geometry>
      <material name="Red">
        <color rgba="1.0 0.0 0.0 1.0"/>
      </material>
    </visual>
    <collision>
      <origin rpy="0 0 0" xyz="0.0 0.0 0.01"/>
      <geometry>
        <cylinder length="0.01" radius="0.005"/>
      </geometry>
    </collision>
    <inertial>
      <mass value="1.96"/>
      <origin rpy="0 0 0" xyz="0.0 0.0 0.01"/>
      <inertia ixx="0.0001143332876" ixy="0.0" ixz="0.0" iyy="0.0001143332876" iyz="0.0" izz="9.8e-05"/>
    </inertial>
  </link>
  <joint name="wrist_1_joint" type="revolute">
    <parent link="forearm_link"/>
    <child link="wrist_1_link"/>
    <origin rpy="0 0 0" xyz="0.0 0.0 0.142"/>
    <axis xyz="0 0 1"/>
    <limit effort="330.0" lower="-3.141592653" upper="3.141592653" velocity="2.16"/>
    <dynamics damping="0.0" friction="0.0"/>
  </joint>
  <!-- Wrist 2 link -->
  <link name="wrist_2_link">
    <visual>
      <origin rpy="0 0 0" xyz="0.0 0.0 0.013"/>
      <geometry>
        <cylinder length="0.026" radius="0.007"/>
      </geometry>
      <material name="Blue">
        <color rgba="0.0 0.0 1.0 1.0"/>
      </material>
    </visual>
    <collision>
      <origin rpy="0 0 0" xyz="0.0 0.0 0.013"/>
      <geometry>
        <cylinder length="0.013" radius="0.0035"/>
      </geometry>
    </collision>
    <inertial>
      <mass value="1.96"/>
      <origin rpy="0 0 0" xyz="0.0 0.0 0.013"/>
      <inertia ixx="0.000134423279564" ixy="0.0" ixz="0.0" iyy="0.000134423279564" iyz="0.0" izz="4.802e-05"/>
    </inertial>
  </link>
  <joint name="wrist_2_joint" type="revolute">
    <parent link="wrist_1_link"/>
    <child link="wrist_2_link"/>
    <origin rpy="0 0 0" xyz="0.0 0.0 0.02"/>
    <axis xyz="0 1 0"/>
    <limit effort="330.0" lower="-3.141592653" upper="3.141592653" velocity="2.16"/>
    <dynamics damping="0.0" friction="0.0"/>
  </joint>
  <!-- Wrist 3 link -->
  <link name="wrist_3_link">
    <visual>
      <origin rpy="0 0 0" xyz="0.0 0.0 0.003"/>
      <geometry>
        <cylinder length="0.006" radius="0.004"/>
      </geometry>
      <material name="Black">
        <color rgba="0.0 0.0 0.0 1.0"/>
      </material>
    </visual>
    <collision>
      <origin rpy="0 0 0" xyz="0.0 0.0 0.003"/>
      <geometry>
        <cylinder length="0.003" radius="0.002"/>
      </geometry>
    </collision>
    <inertial>
      <mass value="0.202"/>
      <origin rpy="0 0 0" xyz="0.0 0.0 0.003"/>
      <inertia ixx="1.4139994344e-06" ixy="0.0" ixz="0.0" iyy="1.4139994344e-06" iyz="0.0" izz="1.616e-06"/>
    </inertial>
  </link>
  <joint name="wrist_3_joint" type="revolute">
    <parent link="wrist_2_link"/>
    <child link="wrist_3_link"/>
    <origin rpy="0 0 0" xyz="0.0 0.0 0.026"/>
    <axis xyz="0 0 1"/>
    <limit effort="330.0" lower="-3.141592653" upper="3.141592653" velocity="2.16"/>
    <dynamics damping="0.0" friction="0.0"/>
  </joint>
  <link name="ee_base">
    <visual>
      <origin rpy="1.5707963265 0 0" xyz="0.0 0.0 0.004"/>
      <geometry>
        <box size="0.012 0.004 0.05"/>
      </geometry>
      <material name="Blue">
        <color rgba="0.0 0.0 1.0 1.0"/>
      </material>
    </visual>
    <collision>
      <origin rpy="1.5707963265 0 0" xyz="0.0 0.0 0.004"/>
      <geometry>
        <box size="0.006 0.002 0.025"/>
      </geometry>
    </collision>
    <inertial>
      <mass value="0.1"/>
      <origin rpy="1.5707963265 0 0" xyz="0.0 0.0 0.004"/>
      <inertia ixx="2.096665828e-05" ixy="0.0" ixz="0.0" iyy="2.203332452e-05" iyz="0.0" izz="2.203332452e-05"/>
    </inertial>
  </link>
  <joint name="ee_footprint_joint" type="fixed">
    <parent link="wrist_3_link"/>
    <child link="ee_base"/>
    <origin rpy="0 0 0" xyz="0.0 0.0 0.006"/>
  </joint>
  <link name="finger1">
    <visual>
      <origin rpy="0 0 0" xyz="0.0 0.0 0.015"/>
      <geometry>
        <box size="0.012 0.002 0.03"/>
      </geometry>
      <material name="Red">
        <color rgba="1.0 0.0 0.0 1.0"/>
      </material>
    </visual>
    <collision>
      <origin rpy="0 0 0" xyz="0.0 0.0 0.015"/>
      <geometry>
        <box size="0.006 0.001 0.015"/>
      </geometry>
    </collision>
    <inertial>
      <mass value="0.1"/>
      <origin rpy="0 0 0" xyz="0.0 0.0 0.015"/>
      <inertia ixx="7.53333032e-06" ixy="0.0" ixz="0.0" iyy="8.69999652e-06" iyz="0.0" izz="8.69999652e-06"/>
    </inertial>
  </link>
  <joint name="finger1_joint" type="prismatic">
    <parent link="ee_base"/>
    <child link="finger1"/>
    <origin rpy="0 0 0" xyz="0.0 -0.025 0.004"/>
    <axis xyz="0 1 0"/>
    <limit effort="330.0" lower="0.0" upper="0.025" velocity="2.16"/>
    <dynamics damping="0.0" friction="0.0"/>
  </joint>
  <link name="finger2">
    <visual>
      <origin rpy="0 0 0" xyz="0.0 0.0 0.015"/>
      <geometry>
        <box size="0.012 0.002 0.03"/>
      </geometry>
      <material name="Red">
        <color rgba="1.0 0.0 0.0 1.0"/>
      </material>
    </visual>
    <collision>
      <origin rpy="0 0 0" xyz="0.0 0.0 0.015"/>
      <geometry>
        <box size="0.006 0.001 0.015"/>
      </geometry>
    </collision>
    <inertial>
      <mass value="0.1"/>
      <origin rpy="0 0 0" xyz="0.0 0.0 0.015"/>
      <inertia ixx="7.53333032e-06" ixy="0.0" ixz="0.0" iyy="8.69999652e-06" iyz="0.0" izz="8.69999652e-06"/>
    </inertial>
  </link>
  <joint name="finger2_joint" type="prismatic">
    <parent link="ee_base"/>
    <child link="finger2"/>
    <origin rpy="0 0 3.141592653" xyz="0.0 0.025 0.004"/>
    <axis xyz="0 1 0"/>
    <limit effort="330.0" lower="0.0" upper="0.025" velocity="2.16"/>
    <dynamics damping="0.0" friction="0.0"/>
  </joint>
</robot>
